Workbook

Sheet Mid-Year Review
B1: 2025 Mid-Year Review
A4: EMPLOYEE INFORMATION | D4: RATING SCALE
A5: Staff ID | B5: PAT00046 | D5: UNACCEPTABLE | E5: 1
A6: Name | B6: =INDEX('Staff list'!C:C,MATCH('Mid-Year Review'!B5,'Staff list'!B:B,0)) -> TOLUWANIMI AKINYEMI | D6: UNACCEPTABLE | E6: 2
A7: Department | B7: =INDEX('Staff list'!D:D,MATCH('Mid-Year Review'!B5,'Staff list'!B:B,0)) -> Technical (NOC) | D7: NEEDS IMPROVEMENT | E7: 3
A8: Unit | B8: =INDEX('Staff list'!D:D,MATCH('Mid-Year Review'!B5,'Staff list'!B:B,0)) -> Technical (NOC) | D8: MEETS EXPECTATION | E8: 4
A9: Role | B9: =INDEX('Staff list'!D:D,MATCH('Mid-Year Review'!B5,'Staff list'!B:B,0)) -> Technical (NOC) | D9: EXCEEDS EXPECTATION | E9: 5
A11: MID-YEAR REVIEW SCORE | B11: =F55 -> 0
A12: MID-YEAR REVIEW RATING | B12: =IF(B11>=101%, "Exceeds Expectation", IF(B11>=80%, "Meets Expectation", IF(B11>=60%, "Needs Improvement", "Unacceptable"))) -> Unacceptable
A15: PAT POLICY INFORMATION | B15: FINAL MID-YEAR/APPRAISAL SCORE IS SUBJECT TO MANAGEMENT REVIEW
A18: OBEJECTIVE, KEY RESULT (OKR) | B18: KEY RESULT AREA (KRA) | C18: WEIGHT | D18: EMPLOYEE SELF RATING | E18: MANAGER RATING | F18: SCORE
A19: {=_xlfn._xlws.FILTER(OKRs!F:F,OKRs!C:C='Mid-Year Review'!B6)} -> NOC Ticket closure rate-MTN | B19: {=_xlfn._xlws.FILTER(OKRs!J:J,OKRs!C:C='Mid-Year Review'!B6)} -> Ensure 70% Daily closure rate of MTN tickets | C19: {=_xlfn._xlws.FILTER(OKRs!H:H,OKRs!C:C='Mid-Year Review'!B6)} -> 0.3 | D19: 4 | F19: =E19/4*C19 -> 0
A20: RCA Accuracy of tickets which matches the on- field actual root causes and resolution (e.g., Trip Breaker for over 2.5 hours is unacceptable or Synchronization failure between Grid-DG, DG powered is not a correct RCA) | B20: Ensure 95% RCA accuracy rate of tickets which matches the on- field actual root causes and resolution | C20: 0.2 | D20: 5 | F20: =E20/4*C20 -> 0
A21: 65% and above sites meeting PA > 99.5% for MTN | B21: 65% and above sites meeting PA > 99.5% for MTN | C21: 0.15 | D21: 5 | F21: =E21/4*C21 -> 0
A22: Ensure average fault count <41 | B22: Ensure average fault count <41 | C22: 0.15 | D22: 5 | F22: =E22/4*C22 -> 0
A23: Ensure MTTR <90minutes | B23: Ensure MTTR <120minutes | C23: 0.1 | D23: 4 | F23: =E23/4*C23 -> 0
A24: Ensure reduction of Passive alarm count | B24: Ensure 1% Monthly reduction of Critical Passive alarm | C24: 0.1 | D24: 4 | F24: =E24/4*C24 -> 0
F25: =E25/4*C25 -> 0
F26: =E26/4*C26 -> 0
F27: =E27/4*C27 -> 0
F28: =E28/4*C28 -> 0
F29: =E29/4*C29 -> 0
F30: =E30/4*C30 -> 0
F31: =E31/4*C31 -> 0
F32: =E32/4*C32 -> 0
F33: =E33/4*C33 -> 0
F34: =E34/4*C34 -> 0
F35: =E35/4*C35 -> 0
F36: =E36/4*C36 -> 0
... F54: =E54/4*C54 -> 0
A55: Total | C55: =SUM(C19:C54) -> 1 | F55: =SUM(F19:F54) -> 0
A58: EMPLOYEE'S COMMENT | B58: I tried all my possible best to meet the expectations of the job given to me, all options of resolution were employed especially with the closure of active running tickets - calls (and follow-up calls) were made to the Huawei NOC and to their managers for the closure of the tickets. The 5-whys method were employed whenever RCAs are given to ascertain the exact root cause of a particular downtime. | C58: =INDEX(OKRs!C:C,MATCH('Mid-Year Review'!B5,OKRs!B:B,0)) -> TOLUWANIMI AKINYEMI
A59: MANAGER'S COMMENT | C59: =INDEX(OKRs!L:L,MATCH('Mid-Year Review'!B5,OKRs!B:B,0)) -> MURTALA ABDULMUMIN

Sheet OKRs
A1: S/N | B1: STAFF ID | C1: STAFF | D1: ROLE | E1: OKRs/KPIs | F1: OKRs 2 | G1: WEIGHT | H1: WEIGHT BROKENDOWN | I1: TARGET | J1: KEY RESULT AREA | K1: COMPANY RESULT | L1: LINE MANAGER
A2: 1 | B2: PAT00097 | C2: ADEJUMOKE AJALA | D2: Key Accounts Executive | E2: Reach commercial objectives | F2: Reach commercial objectives | G2: 0.5 | H2: 0.3 | I2: 80 | J2: Onboard 80 new BTS sites by Q4 2025, ensuring full operational readiness. | L2: ABIMBOLA FALOPE
A3: 1 | B3: PAT00097 | C3: ADEJUMOKE AJALA | D3: Key Accounts Executive | F3: Reach commercial objectives | H3: 0.2 | I3: 150 | J3: Onboard 150 new colo sites by Q4 2025, securing tenant commitments before launch. | L3: ABIMBOLA FALOPE
A4: 1 | B4: PAT00097 | C4: ADEJUMOKE AJALA | D4: Key Accounts Executive | E4: Increase revenue and strengthen commercial agreementsthrough contract renegotiation | F4: Increase revenue and strengthen commercial agreementsthrough contract renegotiation | G4: 0.2 | H4: 0.08 | I4: Nego | J4: Negotiate improved Airtel contract terms beyond the 2024 agreements by Q4 2025. | L4: ABIMBOLA FALOPE
A5: 1 | B5: PAT00097 | C5: ADEJUMOKE AJALA | D5: Key Accounts Executive | F5: Increase revenue and strengthen commercial agreementsthrough contract renegotiation | J5: Complete a full site audit by Q3 2025 to: | L5: ABIMBOLA FALOPE
A6: 1 | B6: PAT00097 | C6: ADEJUMOKE AJALA | D6: Key Accounts Executive | F6: Increase revenue and strengthen commercial agreementsthrough contract renegotiation | H6: 0.08 | I6: Iden | J6: Identify customer equipment across all sites. | L6: ABIMBOLA FALOPE
A7: 1 | B7: PAT00097 | C7: ADEJUMOKE AJALA | D7: Key Accounts Executive | F7: Increase revenue and strengthen commercial agreementsthrough contract renegotiation | H7: 0.04 | J7: Ensure full billing for underbilled sites. | L7: ABIMBOLA FALOPE
A8: 1 | B8: PAT00097 | C8: ADEJUMOKE AJALA | D8: Key Accounts Executive | E8: Enhance Billing Accuracy and Revenue Assurance | F8: Enhance Billing Accuracy and Revenue Assurance | G8: 0.1 | H8: 0.02 | I8: 1 | J8: Achieve 100% accuracy in invoice submissions by Q4 2025, including: | L8: ABIMBOLA FALOPE
A9: 1 | B9: PAT00097 | C9: ADEJUMOKE AJALA | D9: Key Accounts Executive | F9: Enhance Billing Accuracy and Revenue Assurance | H9: 0.07 | I9: 1 | J9: Full and optimal billing for excess power in favor of PAT. | L9: ABIMBOLA FALOPE
A10: 1 | B10: PAT00097 | C10: ADEJUMOKE AJALA | D10: Key Accounts Executive | F10: Enhance Billing Accuracy and Revenue Assurance | H10: 0.01 | I10: 1 | J10: Complete reconciliation of invoices for 100% of sites. | L10: ABIMBOLA FALOPE
A11: 1 | B11: PAT00097 | C11: ADEJUMOKE AJALA | D11: Key Accounts Executive | E11: Ensure high satisfaction from customers | F11: Ensure high satisfaction from customers | G11: 0.1 | H11: 0.075 | I11: 0.85 | J11: Achieve 85% customer satisfaction score through surveys and interviews by Q4 2025. | L11: ABIMBOLA FALOPE
A12: 1 | B12: PAT00097 | C12: ADEJUMOKE AJALA | D12: Key Accounts Executive | F12: Ensure high satisfaction from customers | H12: 0.025 | I12: 0.04 | J12: Conduct quarterly customer feedback sessions to identify areas for service improvement. | L12: ABIMBOLA FALOPE
A13: 1 | B13: PAT00097 | C13: ADEJUMOKE AJALA | D13: Key Accounts Executive | E13: Enhance Commercial Team Performance, Career Growth, and Retention | F13: Enhance Commercial Team Performance, Career Growth, and Retention | G13: 0.05 | H13: 0.02 | I13: 1 | J13: Ensure all commercial staff have OKRs set and aligned with business goals by the end of April 2025. | L13: ABIMBOLA FALOPE
A14: 1 | B14: PAT00097 | C14: ADEJUMOKE AJALA | D14: Key Accounts Executive | F14: Enhance Commercial Team Performance, Career Growth, and Retention | H14: 0.02 | I14: 1 | J14: Collaborate with HR to define a clear career roadmap for all non-field commercial positions and ensure 100% adoption within the team by Q3 2025. | L14: ABIMBOLA FALOPE
A15: 1 | B15: PAT00097 | C15: ADEJUMOKE AJALA | D15: Key Accounts Executive | F15: Enhance Commercial Team Performance, Career Growth, and Retention | H15: 0.01 | I15: Impl | J15: Implement strategies to retain top commercial talent, ensuring attrition of senior personnel does not exceed 5%. | L15: ABIMBOLA FALOPE
A16: 1 | B16: PAT00097 | C16: ADEJUMOKE AJALA | D16: Key Accounts Executive | E16: Ensure Seamless Commercial Integration and Business Continuity Post-ENL Acquisition | F16: Ensure Seamless Commercial Integration and Business Continuity Post-ENL Acquisition | G16: 0.05 | H16: 0.02 | I16: 1 | J16: Ensure a smooth transition of commercial contracts and agreements post-ENL acquisition, with 100% contract review and alignment completed by Q3 2025. | L16: ABIMBOLA FALOPE
A17: 1 | B17: PAT00097 | C17: ADEJUMOKE AJALA | D17: Key Accounts Executive | F17: Ensure Seamless Commercial Integration and Business Continuity Post-ENL Acquisition | H17: 0.01 | I17: 0 | J17: Work closely with Finance and Operations to consolidate and optimize ENL’s customer accounts, ensuring zero revenue leakage and streamlined billing processes. | L17: ABIMBOLA FALOPE
A18: 1 | B18: PAT00097 | C18: ADEJUMOKE AJALA | D18: Key Accounts Executive | F18: Ensure Seamless Commercial Integration and Business Continuity Post-ENL Acquisition | H18: 0.01 | I18: Impl | J18: Provide commercial input for ENL’s financial and operational integration plan, ensuring alignment with PAT’s revenue and growth targets. | L18: ABIMBOLA FALOPE
A19: 1 | B19: PAT00097 | C19: ADEJUMOKE AJALA | D19: Key Accounts Executive | F19: Ensure Seamless Commercial Integration and Business Continuity Post-ENL Acquisition | H19: 0.01 | I19: oversight | J19: Ensure commercial oversight in ENL’s business continuity strategy, mitigating customer churn and maintaining service quality during the transition. | L19: ABIMBOLA FALOPE
A20: 2 | B20: PAT00052 | C20: CAROLINE GBADAMOSI | D20: Key Accounts Manager | E20: Reach commercial objectives | F20: Reach commercial objectives | G20: 0.5 | H20: 0.3 | I20: 80 | J20: Onboard 80 new BTS sites by Q4 2025, ensuring full operational readiness. | L20: AJIBOLA OGUNBADEWA
A21: 2 | B21: PAT00052 | C21: CAROLINE GBADAMOSI | D21: Key Accounts Manager | F21: Reach commercial objectives | H21: 0.2 | I21: 150 | J21: Onboard 150 new colo sites by Q4 2025, securing tenant commitments before launch. | L21: AJIBOLA OGUNBADEWA
A22: 2 | B22: PAT00052 | C22: CAROLINE GBADAMOSI | D22: Key Accounts Manager | E22: Increase revenue and strengthen commercial agreementsthrough contract renegotiation | F22: Increase revenue and strengthen commercial agreementsthrough contract renegotiation | G22: 0.2 | H22: 0.09 | I22: 1 | J22: Successfully conclude MTN contract renegotiation by Q2 2025, ensuring improved financial and operational terms. | L22: AJIBOLA OGUNBADEWA
A23: 2 | B23: PAT00052 | C23: CAROLINE GBADAMOSI | D23: Key Accounts Manager | F23: Increase revenue and strengthen commercial agreementsthrough contract renegotiation | J23: Complete a full site audit by Q3 2025 to: | L23: AJIBOLA OGUNBADEWA
A24: 2 | B24: PAT00052 | C24: CAROLINE GBADAMOSI | D24: Key Accounts Manager | F24: Increase revenue and strengthen commercial agreementsthrough contract renegotiation | H24: 0.07 | I24: Iden | J24: Identify customer equipment across all sites. | L24: AJIBOLA OGUNBADEWA
A25: 2 | B25: PAT00052 | C25: CAROLINE GBADAMOSI | D25: Key Accounts Manager | F25: Increase revenue and strengthen commercial agreementsthrough contract renegotiation | H25: 0.04 | J25: Ensure full billing for underbilled sites. | L25: AJIBOLA OGUNBADEWA
A26: 2 | B26: PAT00052 | C26: CAROLINE GBADAMOSI | D26: Key Accounts Manager | E26: Enhance Billing Accuracy and Revenue Assurance | F26: Enhance Billing Accuracy and Revenue Assurance | G26: 0.1 | H26: 0.02 | I26: 1 | J26: Achieve 100% accuracy in invoice submissions by Q4 2025, including: | L26: AJIBOLA OGUNBADEWA
A27: 2 | B27: PAT00052 | C27: CAROLINE GBADAMOSI | D27: Key Accounts Manager | F27: Enhance Billing Accuracy and Revenue Assurance | H27: 0.07 | I27: 1 | J27: Full and optimal billing for excess power in favor of PAT. | L27: AJIBOLA OGUNBADEWA
A28: 2 | B28: PAT00052 | C28: CAROLINE GBADAMOSI | D28: Key Accounts Manager | F28: Enhance Billing Accuracy and Revenue Assurance | H28: 0.01 | I28: 1 | J28: Complete reconciliation of invoices for 100% of sites. | L28: AJIBOLA OGUNBADEWA
A29: 2 | B29: PAT00052 | C29: CAROLINE GBADAMOSI | D29: Key Accounts Manager | E29: Ensure high satisfaction from customers | F29: Ensure high satisfaction from customers | G29: 0.1 | H29: 0.075 | I29: 0.85 | J29: Achieve 85% customer satisfaction score through surveys and interviews by Q4 2025. | L29: AJIBOLA OGUNBADEWA
A30: 2 | B30: PAT00052 | C30: CAROLINE GBADAMOSI | D30: Key Accounts Manager | F30: Ensure high satisfaction from customers | H30: 0.025 | I30: 0.04 | J30: Conduct quarterly customer feedback sessions to identify areas for service improvement. | L30: AJIBOLA OGUNBADEWA
A31: 2 | B31: PAT00052 | C31: CAROLINE GBADAMOSI | D31: Key Accounts Manager | E31: Enhance Commercial Team Performance, Career Growth, and Retention | F31: Enhance Commercial Team Performance, Career Growth, and Retention | G31: 0.05 | H31: 0.03 | I31: 1 | J31: Ensure OKRs is set and aligned with business goals by the end of April 2025. | L31: AJIBOLA OGUNBADEWA
A32: 2 | B32: PAT00052 | C32: CAROLINE GBADAMOSI | D32: Key Accounts Manager | F32: Enhance Commercial Team Performance, Career Growth, and Retention | H32: 0.02 | I32: 1 | J32: Collaborate with HR to define a clear career roadmap for individual growth by Q3 2025. | L32: AJIBOLA OGUNBADEWA
A33: 2 | B33: PAT00052 | C33: CAROLINE GBADAMOSI | D33: Key Accounts Manager | E33: Ensure Seamless Commercial Integration and Business Continuity Post-ENL Acquisition | F33: Ensure Seamless Commercial Integration and Business Continuity Post-ENL Acquisition | G33: 0.05 | H33: 0.02 | I33: 1 | J33: Ensure a smooth transition of commercial contracts and agreements post-ENL acquisition, with 100% contract review and alignment completed by Q3 2025. | L33: AJIBOLA OGUNBADEWA
A34: 2 | B34: PAT00052 | C34: CAROLINE GBADAMOSI | D34: Key Accounts Manager | F34: Ensure Seamless Commercial Integration and Business Continuity Post-ENL Acquisition | H34: 0.01 | I34: 0 | J34: Work closely with Finance and Operations to consolidate and optimize ENL’s customer accounts, ensuring zero revenue leakage and streamlined billing processes. | L34: AJIBOLA OGUNBADEWA
A35: 2 | B35: PAT00052 | C35: CAROLINE GBADAMOSI | D35: Key Accounts Manager | F35: Ensure Seamless Commercial Integration and Business Continuity Post-ENL Acquisition | H35: 0.01 | I35: Impl | J35: Provide commercial input for ENL’s financial and operational integration plan, ensuring alignment with PAT’s revenue and growth targets. | L35: AJIBOLA OGUNBADEWA
A36: 2 | B36: PAT00052 | C36: CAROLINE GBADAMOSI | D36: Key Accounts Manager | F36: Ensure Seamless Commercial Integration and Business Continuity Post-ENL Acquisition | H36: 0.01 | I36: oversight | J36: Ensure commercial oversight in ENL’s business continuity strategy, mitigating customer churn and maintaining service quality during the transition. | L36: AJIBOLA OGUNBADEWA
A37: 3 | B37: PAT00029 | C37: ABOLAJI ANIMASHAUN | D37: Key Accounts Manager | E37: Reach commercial objectives | F37: Reach commercial objectives | G37: 0.5 | H37: 0.3 | I37: 80 | J37: Onboard 80 new BTS sites by Q4 2025, ensuring full operational readiness. | L37: AJIBOLA OGUNBADEWA
A38: 3 | B38: PAT00029 | C38: ABOLAJI ANIMASHAUN | D38: Key Accounts Manager | F38: Reach commercial objectives | H38: 0.2 | I38: 150 | J38: Onboard 150 new colo sites by Q4 2025, securing tenant commitments before launch. | L38: AJIBOLA OGUNBADEWA
A39: 3 | B39: PAT00029 | C39: ABOLAJI ANIMASHAUN | D39: Key Accounts Manager | E39: Increase revenue and strengthen commercial agreementsthrough contract renegotiation | F39: Increase revenue and strengthen commercial agreementsthrough contract renegotiation | G39: 0.2 | H39: 0.09 | I39: 1 | J39: Successfully conclude MTN contract renegotiation by Q2 2025, ensuring improved financial and operational terms. | L39: AJIBOLA OGUNBADEWA
A40: 3 | B40: PAT00029 | C40: ABOLAJI ANIMASHAUN | D40: Key Accounts Manager | F40: Increase revenue and strengthen commercial agreementsthrough contract renegotiation | J40: Complete a full site audit by Q3 2025 to: | L40: AJIBOLA OGUNBADEWA
...

Sheet Staff list
A1: S/N | B1: Staff ID | C1: Name | D1: Dept | E1: Nomenclature | F1: LOCATION
A2: 1 | B2: PAT00107 | C2: OLADIPO BADRU | D2: Finance | E2: Chief Financial Officer | F2: HQ
A3: 2 | B3: PAT00015 | C3: ARUN PANDA | D3: Technical (CTO) | E3: Chief Technical Officer | F3: HQ
A4: 3 | B4: PAT00164 | C4: AJIBOLA OGUNBADEWA | D4: Commercial | E4: Key Accounts & RF Strategy Lead | F4: HQ
A5: 4 | B5: PAT00155 | C5: ABAYOMI ONITIJU | D5: IT | E5: Chief Information Officer | F5: HQ
A6: 5 | B6: PAT00097 | C6: ADEJUMOKE AJALA | D6: Commercial | E6: Key Accounts Executive | F6: HQ
A7: 6 | B7: PAT00113 | C7: ANTHONY OSAKWE | D7: Technical (DCTO Operations) | E7: Director Technical | F7: HQ
A8: 7 | B8: PAT00027 | C8: CHISOM NDUKWE | D8: HR/Admin | E8: Director, Human Resources & Admin | F8: HQ
A9: 8 | B9: PAT00022 | C9: ABIMBOLA FALOPE | D9: Commercial | E9: Director Commercial | F9: HQ
A10: 9 | B10: PAT00010 | C10: BABATUNDE OLANIYAN | D10: Legal | E10: Director of Legal | F10: HQ
A11: 10 | B11: PAT00110 | C11: SWAPNIL MAHADIK | D11: Technical (Operations) | E11: Head, Operations | F11: HQ
A12: 11 | B12: PAT00028 | C12: NNEAMAKA DIKE | D12: HR/Admin | E12: Head HR Business Partnering | F12: HQ
A13: 12 | B13: PAT00048 | C13: PAUL OBE | D13: IT | E13: IT Team lead | F13: HQ
... A114: 113 | B114: PAT00215 | C114: SIMON ITOK | D114: CEO's office | E114: Driver | F114: HQ

Sheet Sheet2
A1: 1
A2: 2
A3: 3
A4: 4
A5: 5

Sheet Sheet3
